Workbook

Sheet PERGINE
A1: Servizio | B1: Linea | C1: n. corsa | D1: ora part. | E1: ora arr. | F1: percorso | G1: frequenza | H1: Km corsa/servizio | I1: Posti autobus | J1: nr. Gg | K1: Tot km | L1: n° riga | M1: Esito | N1: DITTA | O1: MEZZO TITOLARE | P1: posti mezzo titolare | Q1: MEZZO DI RISERVA 1 | R1: posti mezzo di riserva 1 | S1: MEZZO DI RISERVA 2 | T1: posti mezzo di riserva 2 | U1: MEZZO DI SUPPORTO | V1: posti mezzo di supporto | W1: conferma servizi ditta | X1: frequenza CTA | Y1: tariffa 2025/2026 | Z1: tariffa/km 2025/2026 | AA1: costo annuo | AB1: nota gg (set-mag)
A2: SERVIZIO URBANO PERGINE VALSUGANA | B2: 1 | C2: 487 | D2: 0.29722222 | E2: 0.30555556 | F2: Madrano-Pergine | G2: invernale feriale dal lunedì al sabato | H2: 4.5 | I2: 23 | J2: 218 | K2: =J2*H2 -> 981 | L2: 1 | N2: VALBUS S.R.L. | O2: FL786HC | P2: 24 | Q2: GP809YY | R2: 22 | S2: GP809YY | T2: 22 | X2: invernale feriale lu-sa | Y2: 18.279517 | Z2: 4.0621148 | AA2: =Y2*J2 -> 3984.9346 | AB2: da PDF
A3: SERVIZIO URBANO PERGINE VALSUGANA | B3: 1 | C3: 487 | D3: 0.30069444 | E3: 0.30902778 | F3: Madrano-Pergine | G3: estiva feriale dal lunedì al sabato | H3: 4.5 | I3: 23 | J3: 8 | K3: =J3*H3 -> 36 | L3: 2 | N3: VALBUS S.R.L. | O3: FL786HC | P3: 24 | Q3: GP809YY | R3: 22 | S3: GP809YY | T3: 22 | X3: estiva feriale lu-sa | Y3: 18.279517 | Z3: 4.0621148 | AA3: =Y3*J3 -> 146.23613 | AB3: da PDF
A4: SERVIZIO URBANO PERGINE VALSUGANA | B4: 1 | C4: 422-399 | D4: 0.32986111 | E4: 0.35486111 | F4: Pergine - Nogarè -Nogarè - Pergine | G4: estiva feriale dal lunedì al venerdì | H4: 14 | I4: 22 | J4: 7 | K4: =J4*H4 -> 98 | L4: 3 | N4: VALBUS S.R.L. | O4: FL786HC | P4: 24 | Q4: GP809YY | R4: 22 | S4: GP809YY | T4: 22 | X4: estiva feriale lu-ve | Y4: 56.869607 | Z4: 4.0621148 | AA4: =Y4*J4 -> 398.08725 | AB4: da PDF
A5: SERVIZIO URBANO PERGINE VALSUGANA | B5: 1 | C5: 420-401 | D5: 0.45972222 | E5: 0.48472222 | F5: Pergine - Nogarè -Nogarè - Pergine | G5: invernale feriale dal lunedì al sabato | H5: 14 | I5: 23 | J5: 218 | K5: =J5*H5 -> 3052 | L5: 4 | N5: VALBUS S.R.L. | O5: FL786HC | P5: 24 | Q5: GP809YY | R5: 22 | S5: GP809YY | T5: 22 | X5: invernale feriale lu-sa | Y5: 56.869607 | Z5: 4.0621148 | AA5: =Y5*J5 -> 12397.574 | AB5: da PDF
A6: SERVIZIO URBANO PERGINE VALSUGANA | B6: 1 | C6: 420-401 | D6: 0.45972222 | E6: 0.48472222 | F6: Pergine - Nogarè -Nogarè - Pergine | G6: estiva feriale dal lunedì al sabato | H6: 14 | I6: 22 | J6: 8 | K6: =J6*H6 -> 112 | L6: 5 | N6: VALBUS S.R.L. | O6: FL786HC | P6: 24 | Q6: GP809YY | R6: 22 | S6: GP809YY | T6: 22 | X6: estiva feriale lu-sa | Y6: 56.869607 | Z6: 4.0621148 | AA6: =Y6*J6 -> 454.95686 | AB6: da PDF
A7: SERVIZIO URBANO PERGINE VALSUGANA | B7: 1 | C7: 96-483 | D7: 0.50416667 | E7: 0.52847222 | F7: Pergine - Nogarè -Nogarè - Pergine | G7: scolastica dal lunedì al sabato | H7: 14 | I7: 22 | J7: 198 | K7: =J7*H7 -> 2772 | L7: 6 | N7: ZAMPEDRI STEFANO | O7: GT675ZH | P7: 21 | Q7: FE022HG | R7: 21 | S7: FE022HG | T7: 21 | W7: sì | X7: scolastica lu-sa | Y7: 48.575327 | Z7: 3.4696662 | AA7: =Y7*J7 -> 9617.9147 | AB7: da PDF
A8: SERVIZIO URBANO PERGINE VALSUGANA | B8: 1 | C8: 96 | D8: 0.50416667 | E8: 0.51597222 | F8: Pergine-Nogarè | G8: estiva feriale dal lunedì al venerdì + invernale non scolastico dal lunedì al venerdì | H8: 7 | I8: 22 | J8: 25 | K8: =J8*H8 -> 175 | L8: 7 | N8: ZAMPEDRI STEFANO | O8: GT675ZH | P8: 21 | Q8: FE022HG | R8: 21 | S8: FE022HG | T8: 21 | W8: sì | X8: estiva feriale lu-ve + no scol lu-ve | Y8: 24.287663 | Z8: 3.4696662 | AA8: =Y8*J8 -> 607.19158 | AB8: da PDF
A9: SERVIZIO URBANO PERGINE VALSUGANA | B9: 1 | C9: 96 | D9: 0.50416667 | E9: 0.51597222 | F9: Pergine-Nogarè | G9: estiva feriale solo al sabato + invernale non scolastico solo al sabato | H9: 7 | I9: 22 | J9: 3 | K9: =J9*H9 -> 21 | L9: 8 | N9: ZAMPEDRI STEFANO | O9: GT675ZH | P9: 21 | Q9: FE022HG | R9: 21 | S9: FE022HG | T9: 21 | W9: sì | X9: estiva feriale sa + no scol sa | Y9: 24.287663 | Z9: 3.4696662 | AA9: =Y9*J9 -> 72.86299 | AB9: da PDF
A10: SERVIZIO URBANO PERGINE VALSUGANA | B10: 1 | C10: 97 | D10: 0.55 | E10: 0.56180556 | F10: Nogarè -Pergine | G10: non scolastica feriale dal lunedì al sabato | H10: 7 | I10: 22 | J10: 20 | K10: =J10*H10 -> 140 | L10: 9 | N10: ITALBUS S.N.C. DI CASAGRANDE ARMANDO E CHRISTIAN & C. | O10: GE440VX | P10: 24 | Q10: GP876HE | R10: 23 | S10: EV877GJ | T10: 21 | W10: sì | X10: invernale feriale no scol lu-sa | Y10: 18.117685 | Z10: 2.5882407 | AA10: =Y10*J10 -> 362.3537 | AB10: da PDF
A11: SERVIZIO URBANO PERGINE VALSUGANA | B11: 1 | C11: 97 | D11: 0.55 | E11: 0.56180556 | F11: Nogarè -Pergine | G11: estiva feriale dal lunedì al sabato | H11: 7 | I11: 22 | J11: 8 | K11: =J11*H11 -> 56 | L11: 10 | N11: ITALBUS S.N.C. DI CASAGRANDE ARMANDO E CHRISTIAN & C. | O11: GE440VX | P11: 24 | Q11: GP876HE | R11: 23 | S11: EV877GJ | T11: 21 | W11: sì | X11: estiva feriale lu-sa | Y11: 18.117685 | Z11: 2.5882407 | AA11: =Y11*J11 -> 144.94148 | AB11: da PDF
A12: SERVIZIO URBANO PERGINE VALSUGANA | B12: 1 | C12: 622 | D12: 0.57291667 | E12: 0.57986111 | F12: Pergine-Canzolino | G12: scolastica dal lunedì al venerdì | H12: 4 | I12: 22 | J12: 164 | K12: =J12*H12 -> 656 | L12: 11 | N12: ITALBUS S.N.C. DI CASAGRANDE ARMANDO E CHRISTIAN & C. | O12: GE440VX | P12: 24 | Q12: GP876HE | R12: 23 | S12: EV877GJ | T12: 21 | W12: sì | X12: scolastica lu-ve | Y12: 10.352963 | Z12: 2.5882407 | AA12: =Y12*J12 -> 1697.8859 | AB12: ripartito: blocco PDF su righe sdoppiate (164 + differenza alla gemella)
A13: SERVIZIO URBANO PERGINE VALSUGANA | B13: 1 | C13: 622 | D13: 0.57291667 | E13: 0.57986111 | F13: Pergine-Canzolino | G13: scolastica sabato | H13: 4 | I13: 22 | J13: 34 | K13: =J13*H13 -> 136 | L13: 11 BIS | N13: VALBUS S.R.L. | O13: FL786HC | P13: 24 | Q13: GP809YY | R13: 22 | S13: GP809YY | T13: 22 | W13: sì | X13: scolastica sa | Y13: 16.248459 | Z13: 4.0621148 | AA13: =Y13*J13 -> 552.44761 | AB13: stimato dalla frequenza (riga sdoppiata per corsa)
A14: SERVIZIO URBANO PERGINE VALSUGANA | B14: 1 | C14: 588-589 | D14: 0.67013889 | E14: 0.68263889 | F14: Pergine - Nogarè -Nogarè - Pergine | G14: estiva feriale dal lunedì al venerdì | H14: 14 | I14: 19 | J14: 7 | K14: =J14*H14 -> 98 | L14: 13 | N14: FERSINA TOUR S.R.L | O14: GG078PN | P14: 21 | Q14: FR820WP | R14: 21 | S14: FM703MA | T14: 10 | W14: sì | X14: estiva feriale lu-ve | Y14: 49.1022 | Z14: 3.5073 | AA14: =Y14*J14 -> 343.7154 | AB14: da PDF
A15: SERVIZIO URBANO PERGINE VALSUGANA | B15: 1 | C15: 588-589 | D15: 0.67013889 | E15: 0.69444444 | F15: Pergine - Nogarè -Nogarè - Pergine | G15: invernale feriale dal lunedì al venerdì | H15: 14 | I15: 19 | J15: 182 | K15: =J15*H15 -> 2548 | L15: 14 | N15: FERSINA TOUR S.R.L | O15: GG078PN | P15: 21 | Q15: FR820WP | R15: 21 | S15: FM703MA | T15: 10 | W15: sì | X15: invernale feriale lu-ve | Y15: 49.1022 | Z15: 3.5073 | AA15: =Y15*J15 -> 8936.6004 | AB15: da PDF
A16: SERVIZIO URBANO PERGINE VALSUGANA | B16: 1 | C16: 480-485 | D16: 0.75277778 | E16: 0.77777778 | F16: Pergine - Nogarè -Nogarè - Pergine | G16: invernale feriale dal lunedì al venerdì | H16: 14 | I16: 22 | J16: 182 | K16: =J16*H16 -> 2548 | L16: 15 | N16: ITALBUS S.N.C. DI CASAGRANDE ARMANDO E CHRISTIAN & C. | O16: GE440VX | P16: 24 | Q16: GP876HE | R16: 23 | S16: EV877GJ | T16: 21 | W16: sì | X16: invernale feriale lu-ve | Y16: 36.23537 | Z16: 2.5882407 | AA16: =Y16*J16 -> 6594.8374 | AB16: ripartito: blocco PDF su righe sdoppiate (182 + differenza alla gemella)
A17: SERVIZIO URBANO PERGINE VALSUGANA | B17: 1 | C17: 480-485 | D17: 0.75277778 | E17: 0.77777778 | F17: Pergine - Nogarè -Nogarè - Pergine | G17: estiva feriale dal lunedì al venerdì | H17: 14 | I17: 22 | J17: 7 | K17: =J17*H17 -> 98 | L17: 15 | N17: FERSINA TOUR S.R.L | O17: GG078PN | P17: 21 | Q17: FR820WP | R17: 21 | S17: FM703MA | T17: 10 | X17: estiva feriale lu-ve | Y17: 49.1022 | Z17: 3.5073 | AA17: =Y17*J17 -> 343.7154 | AB17: stimato dalla frequenza (riga sdoppiata per corsa)
A18: SERVIZIO URBANO PERGINE VALSUGANA | B18: 2 | C18: 600 | D18: 0.28125 | E18: 0.30555556 | F18: Pergine-Canezza-Viarago-Serso-Canezza-Pergine | G18: invernale feriale dal lunedì al sabato | H18: 12.8 | I18: 19 | J18: 218 | K18: =J18*H18 -> 2790.4 | L18: 16 | N18: FERSINA TOUR S.R.L | O18: GG078PN | P18: 21 | Q18: FR820WP | R18: 21 | S18: FM703MA | T18: 10 | W18: sì | X18: invernale feriale lu-sa | Y18: 44.89344 | Z18: 3.5073 | AA18: =Y18*J18 -> 9786.7699 | AB18: da PDF
A19: SERVIZIO URBANO PERGINE VALSUGANA | B19: 2 | C19: 600 | D19: 0.28125 | E19: 0.31041667 | F19: Pergine-Canezza-Viarago-Serso-Canezza-Pergine | G19: estiva feriale dal lunedì al sabato | H19: 12.8 | I19: 19 | J19: 8 | K19: =J19*H19 -> 102.4 | L19: 17 | N19: ITALBUS S.N.C. DI CASAGRANDE ARMANDO E CHRISTIAN & C. | O19: GP876HE | P19: 23 | Q19: EV877GJ | R19: 21 | S19: GE440VX | T19: 24 | W19: sì | X19: estiva feriale lu-sa | Y19: 33.129481 | Z19: 2.5882407 | AA19: =Y19*J19 -> 265.03585 | AB19: da PDF
A20: SERVIZIO URBANO PERGINE VALSUGANA | B20: 2 | C20: 602 | D20: 0.46180556 | E20: 0.48402778 | F20: Pergine-Canezza-Viarago-Serso-Canezza-Pergine | G20: estiva feriale dal lunedì al sabato | H20: 12.8 | I20: 19 | J20: 8 | K20: =J20*H20 -> 102.4 | L20: 18 | N20: FERSINA TOUR S.R.L | O20: GG078PN | P20: 21 | Q20: FR820WP | R20: 21 | S20: FM703MA | T20: 10 | W20: sì | X20: estiva feriale lu-sa | Y20: 44.89344 | Z20: 3.5073 | AA20: =Y20*J20 -> 359.14752 | AB20: da PDF
A21: SERVIZIO URBANO PERGINE VALSUGANA | B21: 2 | C21: 604 | D21: 0.71041667 | E21: 0.73958333 | F21: Pergine-Canezza-Viarago-Serso-Canezza-Pergine | G21: invernale feriale dal lunedì al venerdì | H21: 12.8 | I21: 23 | J21: 182 | K21: =J21*H21 -> 2329.6 | L21: 19 | N21: VALBUS S.R.L. | O21: FL786HC | P21: 24 | Q21: GP809YY | R21: 22 | S21: GP809YY | T21: 22 | X21: invernale feriale lu-ve | Y21: 51.995069 | Z21: 4.0621148 | AA21: =Y21*J21 -> 9463.1026 | AB21: da PDF
A22: SERVIZIO URBANO PERGINE VALSUGANA | B22: 2 | C22: 604 | D22: 0.71041667 | E22: 0.73958333 | F22: Pergine-Canezza-Viarago-Serso-Canezza-Pergine | G22: estiva feriale dal lunedì al venerdì | H22: 12.8 | I22: 23 | J22: 7 | K22: =J22*H22 -> 89.6 | L22: 20 | N22: VALBUS S.R.L. | O22: FL786HC | P22: 24 | Q22: GP809YY | R22: 22 | S22: GP809YY | T22: 22 | X22: estiva feriale lu-ve | Y22: 51.995069 | Z22: 4.0621148 | AA22: =Y22*J22 -> 363.96549 | AB22: da PDF
A23: SERVIZIO URBANO PERGINE VALSUGANA | B23: 3 | C23: 475 | D23: 0.3125 | E23: 0.32291667 | F23: Zava-Pergine | G23: scolastica dal lunedì al sabato | H23: 7 | I23: 22 | J23: 198 | K23: =J23*H23 -> 1386 | L23: 21 | N23: VALBUS S.R.L. | O23: FL786HC | P23: 24 | Q23: GP809YY | R23: 22 | S23: GP809YY | T23: 22 | X23: scolastica lu-sa | Y23: 28.434804 | Z23: 4.0621148 | AA23: =Y23*J23 -> 5630.0911 | AB23: da PDF
A24: SERVIZIO URBANO PERGINE VALSUGANA | B24: 3 | C24: 452 | D24: 0.55138889 | E24: 0.5625 | F24: Marie Curie - Pergine - Assizzi-Masetti - Zava | G24: scolastica sabato | H24: 9.3 | I24: 23 | J24: 34 | K24: =J24*H24 -> 316.2 | L24: 22 | N24: VALBUS S.R.L. | O24: FL786HC | P24: 24 | Q24: GP809YY | R24: 22 | S24: GP809YY | T24: 22 | X24: scolastica sa | Y24: 37.777668 | Z24: 4.0621148 | AA24: =Y24*J24 -> 1284.4407 | AB24: da PDF
A25: SERVIZIO URBANO PERGINE VALSUGANA | B25: 3 | C25: 452 | D25: 0.56597222 | E25: 0.57430556 | F25: Pergine - Assizzi-Masetti - Zava | G25: scolastica dal lunedì al venerdì | H25: 9.3 | I25: 23 | J25: 164 | K25: =J25*H25 -> 1525.2 | L25: 23 | N25: VALBUS S.R.L. | O25: FL786HC | P25: 24 | Q25: GP809YY | R25: 22 | S25: GP809YY | T25: 22 | X25: scolastica lu-ve | Y25: 37.777668 | Z25: 4.0621148 | AA25: =Y25*J25 -> 6195.5375 | AB25: da PDF
A26: SERVIZIO URBANO PERGINE VALSUGANA | B26: 4 | C26: 498-505 | D26: 0.35902778 | E26: 0.37291667 | F26: Pergine-Ischia-Ischia-Pergine | G26: estiva feriale dal lunedì al sabato | H26: 9.6 | I26: 22 | J26: 8 | K26: =J26*H26 -> 76.8 | L26: 24 | N26: VALBUS S.R.L. | O26: FL786HC | P26: 24 | Q26: GP809YY | R26: 22 | S26: GP809YY | T26: 22 | X26: estiva feriale lu-sa | Y26: 38.996302 | Z26: 4.0621148 | AA26: =Y26*J26 -> 311.97042 | AB26: da PDF
A27: SERVIZIO URBANO PERGINE VALSUGANA | B27: 4 | C27: 502-509 | D27: 0.48402778 | E27: 0.49791667 | F27: Pergine-Ischia-Ischia-Pergine | G27: feriale dal lunedì al sabato | H27: 9.6 | I27: 20 | J27: 226 | K27: =J27*H27 -> 2169.6 | L27: 25 | N27: ZAMPEDRI STEFANO | O27: GT675ZH | P27: 21 | Q27: FE022HG | R27: 21 | S27: FE022HG | T27: 21 | W27: sì | X27: annuale feriale lu-sa | Y27: 33.308795 | Z27: 3.4696662 | AA27: =Y27*J27 -> 7527.7878 | AB27: da PDF
A28: SERVIZIO URBANO PERGINE VALSUGANA | B28: 4 | C28: 270 | D28: 0.55902778 | E28: 0.56875 | F28: Pergine via S.Pietro-Intermodale-Ischia | G28: scolastica dal lunedì al venerdì | H28: 6.3 | I28: 20 | J28: 164 | K28: =J28*H28 -> 1033.2 | L28: 26 | N28: FERSINA TOUR S.R.L | O28: FZ194KS | P28: 24 | Q28: FR820WP | R28: 21 | S28: FM703MA | T28: 10 | X28: scolastica lu-ve | Y28: 22.09599 | Z28: 3.5073 | AA28: =Y28*J28 -> 3623.7423 | AB28: da PDF
A29: SERVIZIO URBANO PERGINE VALSUGANA | B29: 4 | C29: 504-511 | D29: 0.71180556 | E29: 0.72569444 | F29: Pergine-Ischia-Ischia-Pergine | G29: estiva feriale dal lunedì al venerdì | H29: 9.6 | I29: 20 | J29: 7 | K29: =J29*H29 -> 67.2 | L29: 27 | N29: ZAMPEDRI STEFANO | O29: GT675ZH | P29: 21 | Q29: FE022HG | R29: 21 | S29: FE022HG | T29: 21 | W29: sì | X29: estiva feriale lu-ve | Y29: 33.308795 | Z29: 3.4696662 | AA29: =Y29*J29 -> 233.16157 | AB29: da PDF
A30: SERVIZIO URBANO PERGINE VALSUGANA | B30: 4 | C30: 504-511 | D30: 0.71180556 | E30: 0.73402778 | F30: Pergine-Ischia-Ischia-Pergine | G30: invernale feriale dal lunedì al venerdì | H30: 9.6 | I30: 20 | J30: 182 | K30: =J30*H30 -> 1747.2 | L30: 28 | N30: ZAMPEDRI STEFANO | O30: GT675ZH | P30: 21 | Q30: FE022HG | R30: 21 | S30: FE022HG | T30: 21 | W30: sì | X30: invernale feriale lu-ve | Y30: 33.308795 | Z30: 3.4696662 | AA30: =Y30*J30 -> 6062.2008 | AB30: da PDF
A31: SERVIZIO URBANO PERGINE VALSUGANA | B31: 4 | C31: 504-511 | D31: 0.71875 | E31: 0.72361111 | F31: Ischia - Tenna-Tenna - Ischia | G31: scolastica dal lunedì al venerdì | H31: 7 | I31: 20 | J31: 164 | K31: =J31*H31 -> 1148 | L31: 29 | N31: ZAMPEDRI STEFANO | O31: GT675ZH | P31: 21 | Q31: FE022HG | R31: 21 | S31: FE022HG | T31: 21 | W31: sì | X31: scolastica lu-ve | Y31: 24.287663 | Z31: 3.4696662 | AA31: =Y31*J31 -> 3983.1768 | AB31: da PDF
A32: SERVIZIO URBANO PERGINE VALSUGANA | B32: 5 | C32: 479 | D32: 0.27291667 | E32: 0.28680556 | F32: Masi (Valcanover) - S. Caterina-San Cristoforo | G32: scolastica dal lunedì al sabato | H32: 8 | I32: 20 | J32: 198 | K32: =J32*H32 -> 1584 | L32: 30 | N32: ITALBUS S.N.C. DI CASAGRANDE ARMANDO E CHRISTIAN & C. | O32: EV877GJ | P32: 21 | Q32: GP876HE | R32: 23 | S32: GE440VX | T32: 24 | W32: sì | X32: scolastica lu-sa | Y32: 20.705926 | Z32: 2.5882407 | AA32: =Y32*J32 -> 4099.7733 | AB32: da PDF
A33: SERVIZIO URBANO PERGINE VALSUGANA | B33: 5 | C33: 215 | D33: 0.27916667 | E33: 0.29097222 | F33: Maso Gretter - S.Vito - Susà-Pergine | G33: scolastica dal lunedì al sabato | H33: 5.85 | I33: 23 | J33: 198 | K33: =J33*H33 -> 1158.3 | L33: 31 | N33: ITALBUS S.N.C. DI CASAGRANDE ARMANDO E CHRISTIAN & C. | O33: GE440VX | P33: 24 | Q33: GP876HE | R33: 23 | S33: EV877GJ | T33: 21 | W33: sì | X33: scolastica lu-sa | Y33: 15.141208 | Z33: 2.5882407 | AA33: =Y33*J33 -> 2997.9592 | AB33: da PDF
A34: SERVIZIO URBANO PERGINE VALSUGANA extracapitolato | B34: 5 | C34: 215 | D34: 0.28125 | E34: 0.29097222 | F34: S.Vito-Susà-Pergine | G34: estiva feriale dal lunedì al sabato | H34: 5 | I34: 23 | J34: 8 | K34: =J34*H34 -> 40 | L34: 32 | N34: ITALBUS S.N.C. DI CASAGRANDE ARMANDO E CHRISTIAN & C. | O34: GE440VX | P34: 24 | Q34: GP876HE | R34: 23 | S34: EV877GJ | T34: 21 | W34: sì | X34: estiva feriale lu-sa | Y34: 12.941204 | Z34: 2.5882407 | AA34: =Y34*J34 -> 103.52963 | AB34: da PDF
A35: SERVIZIO URBANO PERGINE VALSUGANA | B35: 5 | C35: 459 | D35: 0.28680556 | E35: 0.31111111 | F35: Masi - S. Caterina- Pergine | G35: scolastica dal lunedì al venerdì | H35: 13.8 | I35: 20 | J35: 164 | K35: =J35*H35 -> 2263.2 | L35: 33 | N35: ITALBUS S.N.C. DI CASAGRANDE ARMANDO E CHRISTIAN & C. | O35: EV877GJ | P35: 21 | Q35: GP876HE | R35: 23 | S35: GE440VX | T35: 24 | W35: sì | X35: scolastica lu-ve | Y35: 35.717722 | Z35: 2.5882407 | AA35: =Y35*J35 -> 5857.7064 | AB35: da PDF
A36: SERVIZIO URBANO PERGINE VALSUGANA | B36: 5 | C36: 459 | D36: 0.30555556 | E36: 0.32777778 | F36: Masi - S. Caterina- Pergine | G36: scolastica sabato | H36: 13.8 | I36: 20 | J36: 34 | K36: =J36*H36 -> 469.2 | L36: 34 | N36: ITALBUS S.N.C. DI CASAGRANDE ARMANDO E CHRISTIAN & C. | O36: EV877GJ | P36: 21 | Q36: GP876HE | R36: 23 | S36: GE440VX | T36: 24 | W36: sì | X36: scolastica sa | Y36: 35.717722 | Z36: 2.5882407 | AA36: =Y36*J36 -> 1214.4025 | AB36: da PDF
A37: SERVIZIO URBANO PERGINE VALSUGANA | B37: 5 | C37: 521 | D37: 0.29513889 | E37: 0.3 | F37: Canale -Pergine (diretta) | G37: scolastica dal lunedì al venerdì | H37: 2.9 | I37: 20 | J37: 164 | K37: =J37*H37 -> 475.6 | L37: 35 | N37: ZAMPEDRI STEFANO | O37: GT675ZH | P37: 21 | Q37: FE022HG | R37: 21 | S37: FE022HG | T37: 21 | W37: sì | X37: scolastica lu-ve | Y37: 10.062032 | Z37: 3.4696662 | AA37: =Y37*J37 -> 1650.1732 | AB37: da PDF
A38: SERVIZIO URBANO PERGINE VALSUGANA | B38: 5 | C38: 521 | D38: 0.3 | E38: 0.30694444 | F38: Canale - Susà- Pergine | G38: estiva feriale dal lunedì al sabato + invernale non scolastico dal lunedì al sabato | H38: 4 | I38: 20 | J38: 28 | K38: =J38*H38 -> 112 | L38: 36 | N38: ZAMPEDRI STEFANO | O38: GT675ZH | P38: 21 | Q38: FE022HG | R38: 21 | S38: FE022HG | T38: 21 | W38: sì | X38: estiva feriale lu-sa + no scol lu-sa | Y38: 13.878665 | Z38: 3.4696662 | AA38: =Y38*J38 -> 388.60261 | AB38: da PDF (testo frequenza troncato nel PDF)
A39: SERVIZIO URBANO PERGINE VALSUGANA | B39: 5 | C39: 521 | D39: 0.3 | E39: 0.30694444 | F39: Canale - Susà- Pergine | G39: scolastica sabato | H39: 4 | I39: 20 | J39: 34 | K39: =J39*H39 -> 136 | L39: 37 | N39: ZAMPEDRI STEFANO | O39: GT675ZH | P39: 21 | Q39: FE022HG | R39: 21 | S39: FE022HG | T39: 21 | W39: sì | X39: scolastica sa | Y39: 13.878665 | Z39: 3.4696662 | AA39: =Y39*J39 -> 471.8746 | AB39: stimato dalla frequenza (riga sdoppiata per corsa)
A40: SERVIZIO URBANO PERGINE VALSUGANA | B40: 5 | C40: 521 | D40: 0.30208333 | E40: 0.30694444 | F40: Susà- Pergine | G40: scolastica dal lunedì al venerdì | H40: 2.3 | I40: 20 | J40: 164 | K40: =J40*H40 -> 377.2 | L40: 38 | N40: ZAMPEDRI STEFANO | O40: GT675ZH | P40: 21 | Q40: FE022HG | R40: 21 | S40: FE022HG | T40: 21 | W40: sì | X40: scolastica lu-ve | Y40: 7.9802323 | Z40: 3.4696662 | AA40: =Y40*J40 -> 1308.7581 | AB40: da PDF
...

Sheet ARCO
A1: Servizio | B1: Linea | C1: n. corsa | D1: ora part. | E1: ora arr. | F1: percorso | G1: frequenza | H1: Km corsa/servizio | I1: Posti autobus | J1: nr. Gg | K1: Tot km | L1: n° riga | M1: Esito | N1: DITTA | O1: MEZZO TITOLARE | P1: posti mezzo titolare | Q1: MEZZO DI RISERVA 1 | R1: posti mezzo di riserva 1 | S1: MEZZO DI RISERVA 2 | T1: posti mezzo di riserva 2 | U1: MEZZO DI SUPPORTO | V1: posti mezzo di supporto | W1: conferma servizi ditta | X1: frequenza CTA | Y1: tariffa 2025/2026 | Z1: tariffa/km 2025/2026 | AA1: costo annuo | AB1: nota gg (set-mag)
A2: SERVIZIO ALTO GARDA (COMUNE DI ARCO) | B2: 869 | C2: 533 | D2: 0.29861111 | E2: 0.31180556 | F2: Campi-Riva del Garda | G2: non scolastica feriale dal lunedì al sabato | H2: 13.9 | I2: 23 | J2: 20 | K2: =J2*H2 -> 278 | L2: 1 | N2: AUTOSERVIZI MATTUZZI CLAUDIO & C. S.N.C. | O2: FB808BJ | P2: 45 | Q2: FL183NW | R2: 33 | S2: GF141FZ | T2: 29 | X2: invernale feriale no scol lu-ve | Y2: 62.02 | AA2: =Y2*J2 -> 1240.4 | AB2: da PDF
A3: SERVIZIO ALTO GARDA (COMUNE DI ARCO) | B3: 869 | C3: 533 | D3: 0.29861111 | E3: 0.31805556 | F3: Campi-Riva v.le Martiri | G3: scolastica dal lunedì al sabato | H3: 14.4 | I3: 44 | J3: 198 | K3: =J3*H3 -> 2851.2 | L3: 2 | N3: AUTOSERVIZI MATTUZZI CLAUDIO & C. S.N.C. | O3: FB808BJ | P3: 45 | Q3: FL183NW | R3: 33 | S3: GF141FZ | T3: 29 | X3: scolastica lu-sa | Y3: 63.12 | AA3: =Y3*J3 -> 12497.76 | AB3: da PDF
A4: SERVIZIO ALTO GARDA (COMUNE DI ARCO) | B4: 869 | C4: 533 | D4: 0.29861111 | E4: 0.31180556 | F4: Campi-Riva del Garda | G4: estiva feriale dal lunedì al sabato | H4: 13.9 | I4: 23 | J4: 8 | K4: =J4*H4 -> 111.2 | L4: 3 | N4: AUTOSERVIZI MATTUZZI CLAUDIO & C. S.N.C. | O4: FB808BJ | P4: 45 | Q4: FL183NW | R4: 33 | S4: GF141FZ | T4: 29 | X4: estiva feriale lu-sa | Y4: 62.02 | AA4: =Y4*J4 -> 496.16 | AB4: da PDF
A5: SERVIZIO ALTO GARDA (COMUNE DI ARCO) | B5: 869 | C5: 555 | D5: 0.54513889 | E5: 0.55833333 | F5: Campi-Riva del Garda | G5: feriale dal lunedì al sabato | H5: 13.9 | I5: 23 | J5: 226 | K5: =J5*H5 -> 3141.4 | L5: 4 | N5: AUTOSERVIZI MATTUZZI CLAUDIO & C. S.N.C. | O5: FL183NW | P5: 33 | Q5: GY436PZ | R5: 24 | S5: GF141FZ | T5: 29 | X5: annuale feriale lu-sa | Y5: 31.07 | AA5: =Y5*J5 -> 7021.82 | AB5: da PDF
A6: SERVIZIO ALTO GARDA (COMUNE DI ARCO) | B6: 869 | C6: 557 | D6: 0.57638889 | E6: 0.58958333 | F6: Campi-Riva del Garda | G6: scolastica dal lunedì al sabato | H6: 13.9 | I6: 23 | J6: 198 | K6: =J6*H6 -> 2752.2 | L6: 5 | N6: AUTOSERVIZI MATTUZZI CLAUDIO & C. S.N.C. | O6: GY436PZ | P6: 24 | Q6: FL183NW | R6: 33 | S6: GF141FZ | T6: 29 | X6: scolastica lu-sa | Y6: 31.07 | AA6: =Y6*J6 -> 6151.86 | AB6: da PDF
A7: SERVIZIO ALTO GARDA (COMUNE DI ARCO) | B7: 869 | C7: 554 | D7: 0.52569444 | E7: 0.54305556 | F7: Riva v.le Martiri-Campi | G7: feriale dal lunedì al sabato | H7: 13.9 | I7: 23 | J7: 226 | K7: =J7*H7 -> 3141.4 | L7: 6 | N7: AUTOSERVIZI MATTUZZI CLAUDIO & C. S.N.C. | O7: GY436PZ | P7: 24 | Q7: FL183NW | R7: 33 | S7: GF141FZ | T7: 29 | X7: annuale feriale lu-sa | Y7: 31.07 | AA7: =Y7*J7 -> 7021.82 | AB7: da PDF
A8: SERVIZIO ALTO GARDA (COMUNE DI ARCO) | B8: 869 | C8: 556 | D8: 0.55833333 | E8: 0.57638889 | F8: Riva v.le Martiri-Campi | G8: scolastica dal lunedì al sabato | H8: 12 | I8: 23 | J8: 198 | K8: =J8*H8 -> 2376 | L8: 7 | N8: AUTOSERVIZI MATTUZZI CLAUDIO & C. S.N.C. | O8: GY436PZ | P8: 24 | Q8: FL183NW | R8: 33 | S8: GF141FZ | T8: 29 | X8: scolastica lu-sa | Y8: 26.83 | AA8: =Y8*J8 -> 5312.34 | AB8: da PDF
A9: SERVIZIO ALTO GARDA (COMUNE DI ARCO) | B9: 869 | C9: 560 | D9: 0.59375 | E9: 0.60763889 | F9: Riva d.G-Campi | G9: scolastica dal lunedì al venerdì | H9: 12 | I9: 23 | J9: 164 | K9: =J9*H9 -> 1968 | L9: 8 | N9: AUTOSERVIZI MATTUZZI CLAUDIO & C. S.N.C. | O9: GY436PZ | P9: 24 | Q9: FL183NW | R9: 33 | S9: GF141FZ | T9: 29 | X9: scolastica lu-ve | Y9: 26.83 | AA9: =Y9*J9 -> 4400.12 | AB9: da PDF
A10: SERVIZIO ALTO GARDA (COMUNE DI ARCO) | B10: 869 | C10: 558 | D10: 0.75694444 | E10: 0.77777778 | F10: Riva v.le Martiri-Campi | G10: feriale dal lunedì al sabato | H10: 13.9 | I10: 23 | J10: 226 | K10: =J10*H10 -> 3141.4 | L10: 9 | N10: AUTOSERVIZI MATTUZZI CLAUDIO & C. S.N.C. | O10: GY436PZ | P10: 24 | Q10: FL183NW | R10: 33 | S10: GF141FZ | T10: 29 | X10: annuale feriale lu-sa | Y10: 62.02 | AA10: =Y10*J10 -> 14016.52 | AB10: da PDF
A11: SERVIZIO ALTO GARDA (COMUNE DI ARCO) | B11: 863 | C11: 803 | D11: 0.32638889 | E11: 0.33402778 | F11: Riva d.G.-Arco | G11: scolastica dal lunedì al venerdì | H11: 6 | I11: 23 | J11: 164 | K11: =J11*H11 -> 984 | L11: 10 | N11: SOLETANA VIAGGI S.R.L. | O11: FJ863YE | P11: 56 | Q11: GW667HX | R11: 53 | S11: FH513LD | T11: 56 | X11: scolastica lu-ve | Y11: 152.4 | AA11: =Y11*J11 -> 24993.6 | AB11: da PDF
A12: SERVIZIO ALTO GARDA (COMUNE DI ARCO) | B12: 862 | C12: 501 | D12: 0.31319444 | E12: 0.32013889 | F12: Varone Sega-Riva del Garda | G12: scolastica dal lunedì al venerdì | H12: 4 | I12: 50 | J12: 164 | K12: =J12*H12 -> 656 | L12: 11 | N12: AUTOSERVIZI MATTUZZI CLAUDIO & C. S.N.C. | O12: GT606ZH | P12: 55 | Q12: FE584HG | R12: 56 | S12: FZ760BE | T12: 54 | X12: scolastica lu-ve | Y12: 18.29 | AA12: =Y12*J12 -> 2999.56 | AB12: da PDF
H13: TOTALE | K13: =SUM(K2:K12) -> 21400.8 | L13: sett-magg | AA13: =SUM(AA2:AA12) -> 86151.96 | AB13: sett-magg
K15: ='ARCO giu-ago'!K13 -> 4791.6 | L15: giu-ago | AA15: ='ARCO giu-ago'!AA13 -> 16960.06 | AB15: giu-ago
K17: =SUM(K13:K16) -> 26192.4 | AA17: =SUM(AA13:AA16) -> 103112.02
K19: 21400.8 | AA19: 86151.96
K21: 4791.6 | AA21: 16960.06
K23: 26192.4 | AA23: 103112.02
K25: =K19-K13 -> 0 | AA25: =AA19-AA13 -> 0
K26: =K15-K21 -> 0 | AA26: =AA15-AA21 -> 0
K27: =K17-K23 -> 0 | AA27: =AA17-AA23 -> 0

Sheet LAVIS
A1: Servizio | B1: Linea | C1: n. corsa | D1: ora part. | E1: ora arr. | F1: percorso | G1: frequenza | H1: Km corsa/servizio | I1: Posti autobus | J1: nr. Gg | K1: Tot km | L1: n° riga | M1: Esito | N1: DITTA | O1: MEZZO TITOLARE | P1: posti mezzo titolare | Q1: MEZZO DI RISERVA 1 | R1: posti mezzo di riserva 1 | S1: MEZZO DI RISERVA 2 | T1: posti mezzo di riserva 2 | U1: MEZZO DI SUPPORTO | V1: posti mezzo di supporto | W1: conferma servizi ditta | X1: frequenza CTA | Y1: tariffa 2025/2026 | Z1: tariffa/km 2025/2026 | AA1: costo annuo | AB1: nota gg (set-mag)
A2: T.M. L.1 - Linea L1 - LAVIS | B2: 10 | C2: L01101 n5 | D2: 0.27222222 | E2: 0.27430556 | F2: SORNI bivio - SORNI | G2: Non scolastica da Lunedì a Venerdì (estate + invernale) | H2: 1.13 | I2: 19 | J2: 25 | K2: =J2*H2 -> 28.25 | L2: 1 | N2: ELIMA SRL | O2: GL794HS | P2: 23 | Q2: GP595HE | R2: 21 | W2: sì | X2: estiva feriale lu-ve + no scol lu-ve | Y2: 2.9161232 | Z2: 2.58064 | AA2: =Y2*J2 -> 72.90308 | AB2: da PDF (ordine posizionale)
A3: T.M. L.1 - Linea L1 - LAVIS | B3: 20 | C3: L01151 n5 | D3: 0.27430556 | E3: 0.28958333 | F3: SORNI - LAVIS via Nazionale | G3: Non scolastica da Lunedì a Venerdì (estate + invernale) | H3: 9.01 | I3: 19 | J3: 25 | K3: =J3*H3 -> 225.25 | L3: 2 | N3: ELIMA SRL | O3: GL794HS | P3: 23 | Q3: GP595HE | R3: 21 | W3: sì | X3: estiva feriale lu-ve + no scol lu-ve | Y3: 23.251566 | Z3: 2.58064 | AA3: =Y3*J3 -> 581.28916 | AB3: da PDF (ordine posizionale)
A4: T.M. L.1 - Linea L1 - LAVIS | B4: 30 | C4: L01102 | D4: 0.31805556 | E4: 0.33055556 | F4: LAVIS via Nazionale - SORNI | G4: Non scolastica da Lunedì a Venerdì (estate + invernale) | H4: 7.67 | I4: 19 | J4: 25 | K4: =J4*H4 -> 191.75 | L4: 3 | N4: ELIMA SRL | O4: GL794HS | P4: 23 | Q4: GP595HE | R4: 21 | W4: sì | X4: estiva feriale lu-ve + no scol lu-ve | Y4: 19.793509 | Z4: 2.58064 | AA4: =Y4*J4 -> 494.83772 | AB4: da PDF (ordine posizionale)
A5: T.M. L.1 - Linea L1 - LAVIS | B5: 40 | C5: L01152 | D5: 0.33541667 | E5: 0.35069444 | F5: SORNI - LAVIS via Nazionale | G5: Non scolastica da Lunedì a Venerdì (estate + invernale) | H5: 9.01 | I5: 19 | J5: 25 | K5: =J5*H5 -> 225.25 | L5: 4 | N5: ELIMA SRL | O5: GL794HS | P5: 23 | Q5: GP595HE | R5: 21 | W5: sì | X5: estiva feriale lu-ve + no scol lu-ve | Y5: 23.251566 | Z5: 2.58064 | AA5: =Y5*J5 -> 581.28916 | AB5: da PDF (ordine posizionale)
A6: T.M. L.1 - Linea L1 - LAVIS | B6: 50 | C6: L01103 | D6: 0.35972222 | E6: 0.37222222 | F6: LAVIS via Nazionale - SORNI | G6: Non scolastica da Lunedì a Venerdì (estate + invernale) | H6: 7.67 | I6: 19 | J6: 25 | K6: =J6*H6 -> 191.75 | L6: 5 | N6: ELIMA SRL | O6: GL794HS | P6: 23 | Q6: GP595HE | R6: 21 | W6: sì | X6: estiva feriale lu-ve + no scol lu-ve | Y6: 19.793509 | Z6: 2.58064 | AA6: =Y6*J6 -> 494.83772 | AB6: da PDF (ordine posizionale)
A7: T.M. L.1 - Linea L1 - LAVIS | B7: 60 | C7: L01153 | D7: 0.37708333 | E7: 0.39236111 | F7: SORNI - LAVIS via Nazionale | G7: Non scolastica da Lunedì a Venerdì (estate + invernale) | H7: 9.01 | I7: 19 | J7: 25 | K7: =J7*H7 -> 225.25 | L7: 6 | N7: ELIMA SRL | O7: GL794HS | P7: 23 | Q7: GP595HE | R7: 21 | W7: sì | X7: estiva feriale lu-ve + no scol lu-ve | Y7: 23.251566 | Z7: 2.58064 | AA7: =Y7*J7 -> 581.28916 | AB7: da PDF (ordine posizionale)
A8: T.M. L.1 - Linea L1 - LAVIS | B8: 70 | C8: L01104 | D8: 0.46458333 | E8: 0.47708333 | F8: LAVIS via Nazionale - SORNI | G8: Non scolastica da Lunedì a Venerdì (estate + invernale) | H8: 7.67 | I8: 19 | J8: 25 | K8: =J8*H8 -> 191.75 | L8: 7 | N8: ELIMA SRL | O8: GL794HS | P8: 23 | Q8: GP595HE | R8: 21 | W8: sì | X8: estiva feriale lu-ve + no scol lu-ve | Y8: 19.793509 | Z8: 2.58064 | AA8: =Y8*J8 -> 494.83772 | AB8: da PDF (ordine posizionale)
A9: T.M. L.1 - Linea L1 - LAVIS | B9: 80 | C9: L01154 | D9: 0.47708333 | E9: 0.49236111 | F9: SORNI - LAVIS via Nazionale | G9: Non scolastica da Lunedì a Venerdì (estate + invernale) | H9: 9.01 | I9: 19 | J9: 25 | K9: =J9*H9 -> 225.25 | L9: 8 | N9: ELIMA SRL | O9: GL794HS | P9: 23 | Q9: GP595HE | R9: 21 | W9: sì | X9: estiva feriale lu-ve + no scol lu-ve | Y9: 23.251566 | Z9: 2.58064 | AA9: =Y9*J9 -> 581.28916 | AB9: da PDF (ordine posizionale)
A10: T.M. L.1 - Linea L1 - LAVIS | B10: 90 | C10: L01105 | D10: 0.54791667 | E10: 0.56041667 | F10: LAVIS via Nazionale - SORNI | G10: Non scolastica da Lunedì a Venerdì (estate + invernale) | H10: 7.67 | I10: 19 | J10: 25 | K10: =J10*H10 -> 191.75 | L10: 9 | N10: ELIMA SRL | O10: GL794HS | P10: 23 | Q10: GP595HE | R10: 21 | W10: sì | X10: estiva feriale lu-ve + no scol lu-ve | Y10: 19.793509 | Z10: 2.58064 | AA10: =Y10*J10 -> 494.83772 | AB10: da PDF (ordine posizionale)
A11: T.M. L.1 - Linea L1 - LAVIS | B11: 100 | C11: L01155 | D11: 0.56041667 | E11: 0.57569444 | F11: SORNI - LAVIS via Nazionale | G11: Non scolastica da Lunedì a Venerdì (estate + invernale) | H11: 9.01 | I11: 19 | J11: 25 | K11: =J11*H11 -> 225.25 | L11: 10 | N11: ELIMA SRL | O11: GL794HS | P11: 23 | Q11: GP595HE | R11: 21 | W11: sì | X11: estiva feriale lu-ve + no scol lu-ve | Y11: 23.251566 | Z11: 2.58064 | AA11: =Y11*J11 -> 581.28916 | AB11: da PDF (ordine posizionale)
A12: T.M. L.1 - Linea L1 - LAVIS | B12: 110 | C12: L01106 n5 | D12: 0.58958333 | E12: 0.60208333 | F12: LAVIS via Nazionale - SORNI | G12: Non scolastica da Lunedì a Venerdì (estate + invernale) | H12: 7.67 | I12: 19 | J12: 25 | K12: =J12*H12 -> 191.75 | L12: 11 | N12: ELIMA SRL | O12: GL794HS | P12: 23 | Q12: GP595HE | R12: 21 | W12: sì | X12: estiva feriale lu-ve + no scol lu-ve | Y12: 19.793509 | Z12: 2.58064 | AA12: =Y12*J12 -> 494.83772 | AB12: da PDF (ordine posizionale)
A13: T.M. L.1 - Linea L1 - LAVIS | B13: 120 | C13: L01156 n5 | D13: 0.60208333 | E13: 0.61736111 | F13: SORNI - LAVIS via Nazionale | G13: Non scolastica da Lunedì a Venerdì (estate + invernale) | H13: 9.01 | I13: 19 | J13: 25 | K13: =J13*H13 -> 225.25 | L13: 12 | N13: ELIMA SRL | O13: GL794HS | P13: 23 | Q13: GP595HE | R13: 21 | W13: sì | X13: estiva feriale lu-ve + no scol lu-ve | Y13: 23.251566 | Z13: 2.58064 | AA13: =Y13*J13 -> 581.28916 | AB13: da PDF (ordine posizionale)
... A53: T.M. L.1 - Linea L1 - LAVIS | B53: 160 | C53: L01161 | D53: 0.78472222 | E53: 0.79027778 | F53: PRESSANO Piazza - LAVIS via Nazionale | G53: Non scolastica solo il Sabato (estate + invernale) | H53: 2.76 | I53: 19 | J53: 3 | K53: =J53*H53 -> 8.28 | L53: 52 | N53: ELIMA SRL | O53: GL794HS | P53: 23 | Q53: GP595HE | R53: 21 | W53: sì | X53: estiva feriale sa + no scol sa | Y53: 7.1225664 | Z53: 2.58064 | AA53: =Y53*J53 -> 21.367699 | AB53: da PDF (ordine posizionale)
A54: T.M. L.1 - Linee L1 e L2 LAVIS | B54: 10 | C54: L01151 s6 | D54: 0.27430556 | E54: 0.28958333 | F54: SORNI - LAVIS via Nazionale | G54: /S colastica da Lunedì a Venerdì | H54: 9.76 | I54: 21 | J54: 164 | K54: =J54*H54 -> 1600.64 | L54: 53 | N54: OSCAR VIAGGI DI FORMOLO OSCAR | O54: GX220WF | P54: 21 | Q54: GZ064ZJ | R54: 21 | S54: GX166WF | W54: sì | X54: scolastica lu-ve | Y54: 25.187046 | Z54: 2.58064 | AA54: =Y54*J54 -> 4130.6756 | AB54: da PDF (ordine posizionale)
A55: T.M. L.1 - Linee L1 e L2 LAVIS | B55: 20 | C55: L01102 | D55: 0.31805556 | E55: 0.33055556 | F55: LAVIS via Nazionale - SORNI | G55: /S colastica da Lunedì a Venerdì | H55: 7.67 | I55: 19 | J55: 164 | K55: =J55*H55 -> 1257.88 | L55: 54 | N55: ELIMA SRL | O55: GL794HS | P55: 23 | Q55: GP595HE | R55: 21 | W55: sì | X55: scolastica lu-ve | Y55: 19.793509 | Z55: 2.58064 | AA55: =Y55*J55 -> 3246.1354 | AB55: da PDF (ordine posizionale)
A56: T.M. L.1 - Linee L1 e L2 LAVIS | B56: 30 | C56: L01152 | D56: 0.33541667 | E56: 0.35069444 | F56: SORNI - LAVIS via Nazionale | G56: /S colastica da Lunedì a Venerdì | H56: 9.01 | I56: 19 | J56: 164 | K56: =J56*H56 -> 1477.64 | L56: 55 | N56: ELIMA SRL | O56: GL794HS | P56: 23 | Q56: GP595HE | R56: 21 | W56: sì | X56: scolastica lu-ve | Y56: 23.251566 | Z56: 2.58064 | AA56: =Y56*J56 -> 3813.2569 | AB56: da PDF (ordine posizionale)
A57: T.M. L.1 - Linee L1 e L2 LAVIS | B57: 40 | C57: L01103 | D57: 0.35972222 | E57: 0.37222222 | F57: LAVIS via Nazionale - SORNI | G57: /S colastica da Lunedì a Venerdì | H57: 7.67 | I57: 19 | J57: 164 | K57: =J57*H57 -> 1257.88 | L57: 56 | N57: ELIMA SRL | O57: GL794HS | P57: 23 | Q57: GP595HE | R57: 21 | W57: sì | X57: scolastica lu-ve | Y57: 19.793509 | Z57: 2.58064 | AA57: =Y57*J57 -> 3246.1354 | AB57: da PDF (ordine posizionale)
A58: T.M. L.1 - Linee L1 e L2 LAVIS | B58: 50 | C58: L01153 | D58: 0.37708333 | E58: 0.39236111 | F58: SORNI - LAVIS via Nazionale | G58: /S colastica da Lunedì a Venerdì | H58: 9.01 | I58: 19 | J58: 164 | K58: =J58*H58 -> 1477.64 | L58: 57 | N58: ELIMA SRL | O58: GL794HS | P58: 23 | Q58: GP595HE | R58: 21 | W58: sì | X58: scolastica lu-ve | Y58: 23.251566 | Z58: 2.58064 | AA58: =Y58*J58 -> 3813.2569 | AB58: da PDF (ordine posizionale)
A59: T.M. L.1 - Linee L1 e L2 LAVIS | B59: 60 | C59: L01104 | D59: 0.46458333 | E59: 0.47708333 | F59: LAVIS via Nazionale - SORNI | G59: /S colastica da Lunedì a Venerdì | H59: 7.67 | I59: 19 | J59: 164 | K59: =J59*H59 -> 1257.88 | L59: 58 | N59: ELIMA SRL | O59: GL794HS | P59: 23 | Q59: GP595HE | R59: 21 | W59: sì | X59: scolastica lu-ve | Y59: 19.793509 | Z59: 2.58064 | AA59: =Y59*J59 -> 3246.1354 | AB59: da PDF (ordine posizionale)
A60: T.M. L.1 - Linee L1 e L2 LAVIS | B60: 70 | C60: L01154 | D60: 0.47708333 | E60: 0.49236111 | F60: SORNI - LAVIS via Nazionale | G60: /S colastica da Lunedì a Venerdì | H60: 9.01 | I60: 19 | J60: 164 | K60: =J60*H60 -> 1477.64 | L60: 59 | N60: ELIMA SRL | O60: GL794HS | P60: 23 | Q60: GP595HE | R60: 21 | W60: sì | X60: scolastica lu-ve | Y60: 23.251566 | Z60: 2.58064 | AA60: =Y60*J60 -> 3813.2569 | AB60: da PDF (ordine posizionale)
A61: T.M. L.1 - Linee L1 e L2 LAVIS | B61: 80 | C61: L01105 | D61: 0.54791667 | E61: 0.56041667 | F61: LAVIS via Nazionale - SORNI | G61: /S colastica da Lunedì a Venerdì | H61: 7.67 | I61: 19 | J61: 164 | K61: =J61*H61 -> 1257.88 | L61: 60 | N61: ELIMA SRL | O61: GL794HS | P61: 23 | Q61: GP595HE | R61: 21 | W61: sì | X61: scolastica lu-ve | Y61: 19.793509 | Z61: 2.58064 | AA61: =Y61*J61 -> 3246.1354 | AB61: da PDF (ordine posizionale)
A62: T.M. L.1 - Linee L1 e L2 LAVIS | B62: 90 | C62: L01155 | D62: 0.56041667 | E62: 0.57569444 | F62: SORNI - LAVIS via Nazionale | G62: /S colastica da Lunedì a Venerdì | H62: 9.01 | I62: 19 | J62: 164 | K62: =J62*H62 -> 1477.64 | L62: 61 | N62: ELIMA SRL | O62: GL794HS | P62: 23 | Q62: GP595HE | R62: 21 | W62: sì | X62: scolastica lu-ve | Y62: 23.251566 | Z62: 2.58064 | AA62: =Y62*J62 -> 3813.2569 | AB62: da PDF (ordine posizionale)
A63: T.M. L.1 - Linee L1 e L2 LAVIS | B63: 100 | C63: L02103 s5 | D63: 0.59305556 | E63: 0.60277778 | F63: LAVIS via Nazionale - SORNI | G63: /S colastica da Lunedì a Venerdì | H63: 7.07 | I63: 21 | J63: 164 | K63: =J63*H63 -> 1159.48 | L63: 62 | N63: OSCAR VIAGGI DI FORMOLO OSCAR | O63: GX220WF | P63: 21 | Q63: GZ064ZJ | R63: 21 | S63: GX166WF | W63: sì | X63: scolastica lu-ve | Y63: 18.245125 | Z63: 2.58064 | AA63: =Y63*J63 -> 2992.2005 | AB63: da PDF (ordine posizionale)
A64: T.M. L.1 - Linee L1 e L2 LAVIS | B64: 110 | C64: L02153 s5 | D64: 0.60277778 | E64: 0.61527778 | F64: SORNI - LAVIS via Nazionale | G64: /S colastica da Lunedì a Venerdì | H64: 7.82 | I64: 21 | J64: 164 | K64: =J64*H64 -> 1282.48 | L64: 63 | N64: OSCAR VIAGGI DI FORMOLO OSCAR | O64: GX220WF | P64: 21 | Q64: GZ064ZJ | R64: 21 | S64: GX166WF | W64: sì | X64: scolastica lu-ve | Y64: 20.180605 | Z64: 2.58064 | AA64: =Y64*J64 -> 3309.6192 | AB64: da PDF (ordine posizionale)
A65: T.M. L.1 - Linee L1 e L2 LAVIS | B65: 120 | C65: L01107 LV | D65: 0.63125 | E65: 0.64375 | F65: LAVIS via Nazionale - SORNI | G65: /S colastica da Lunedì a Venerdì | H65: 7.67 | I65: 19 | J65: 164 | K65: =J65*H65 -> 1257.88 | L65: 64 | N65: ELIMA SRL | O65: GL794HS | P65: 23 | Q65: GP595HE | R65: 21 | W65: sì | X65: scolastica lu-ve | Y65: 19.793509 | Z65: 2.58064 | AA65: =Y65*J65 -> 3246.1354 | AB65: da PDF (ordine posizionale)
A66: T.M. L.1 - Linee L1 e L2 LAVIS | B66: 130 | C66: L01157 LV | D66: 0.64375 | E66: 0.65902778 | F66: SORNI - LAVIS via Nazionale | G66: /S colastica da Lunedì a Venerdì | H66: 9.01 | I66: 19 | J66: 164 | K66: =J66*H66 -> 1477.64 | L66: 65 | N66: ELIMA SRL | O66: GL794HS | P66: 23 | Q66: GP595HE | R66: 21 | W66: sì | X66: scolastica lu-ve | Y66: 23.251566 | Z66: 2.58064 | AA66: =Y66*J66 -> 3813.2569 | AB66: da PDF (ordine posizionale)
A67: T.M. L.1 - Linee L1 e L2 LAVIS | B67: 140 | C67: L01108 | D67: 0.65902778 | E67: 0.66666667 | F67: LAVIS via Nazionale - PRESSANO Piazza | G67: /S colastica da Lunedì a Venerdì | H67: 3.76 | I67: 19 | J67: 164 | K67: =J67*H67 -> 616.64 | L67: 66 | N67: ELIMA SRL | O67: GL794HS | P67: 23 | Q67: GP595HE | R67: 21 | W67: sì | X67: scolastica lu-ve | Y67: 9.7032064 | Z67: 2.58064 | AA67: =Y67*J67 -> 1591.3258 | AB67: da PDF (ordine posizionale)
A68: T.M. L.1 - Linee L1 e L2 LAVIS | B68: 150 | C68: L01158 | D68: 0.66666667 | E68: 0.67222222 | F68: PRESSANO Piazza - LAVIS via Nazionale | G68: /S colastica da Lunedì a Venerdì | H68: 2.76 | I68: 19 | J68: 164 | K68: =J68*H68 -> 452.64 | L68: 67 | N68: ELIMA SRL | O68: GL794HS | P68: 23 | Q68: GP595HE | R68: 21 | W68: sì | X68: scolastica lu-ve | Y68: 7.1225664 | Z68: 2.58064 | AA68: =Y68*J68 -> 1168.1009 | AB68: da PDF (ordine posizionale)
A69: T.M. L.1 - Linee L1 e L2 LAVIS | B69: 160 | C69: L01109 LV | D69: 0.67291667 | E69: 0.68541667 | F69: LAVIS via Nazionale - SORNI | G69: /S colastica da Lunedì a Venerdì | H69: 7.67 | I69: 19 | J69: 164 | K69: =J69*H69 -> 1257.88 | L69: 68 | N69: ELIMA SRL | O69: GL794HS | P69: 23 | Q69: GP595HE | R69: 21 | W69: sì | X69: scolastica lu-ve | Y69: 19.793509 | Z69: 2.58064 | AA69: =Y69*J69 -> 3246.1354 | AB69: da PDF (ordine posizionale)
A70: T.M. L.1 - Linee L1 e L2 LAVIS | B70: 170 | C70: L01159 LV | D70: 0.68541667 | E70: 0.70069444 | F70: SORNI - LAVIS via Nazionale | G70: /S colastica da Lunedì a Venerdì | H70: 9.01 | I70: 19 | J70: 164 | K70: =J70*H70 -> 1477.64 | L70: 69 | N70: ELIMA SRL | O70: GL794HS | P70: 23 | Q70: GP595HE | R70: 21 | W70: sì | X70: scolastica lu-ve | Y70: 23.251566 | Z70: 2.58064 | AA70: =Y70*J70 -> 3813.2569 | AB70: da PDF (ordine posizionale)
A71: T.M. L.1 - Linee L1 e L2 LAVIS | B71: 180 | C71: L01110 | D71: 0.71458333 | E71: 0.72708333 | F71: LAVIS via Nazionale - SORNI | G71: /S colastica da Lunedì a Venerdì | H71: 7.67 | I71: 19 | J71: 164 | K71: =J71*H71 -> 1257.88 | L71: 70 | N71: ELIMA SRL | O71: GL794HS | P71: 23 | Q71: GP595HE | R71: 21 | W71: sì | X71: scolastica lu-ve | Y71: 19.793509 | Z71: 2.58064 | AA71: =Y71*J71 -> 3246.1354 | AB71: da PDF (ordine posizionale)
A72: T.M. L.1 - Linee L1 e L2 LAVIS | B72: 190 | C72: L01160 | D72: 0.72708333 | E72: 0.74236111 | F72: SORNI - LAVIS via Nazionale | G72: /S colastica da Lunedì a Venerdì | H72: 9.01 | I72: 19 | J72: 164 | K72: =J72*H72 -> 1477.64 | L72: 71 | N72: ELIMA SRL | O72: GL794HS | P72: 23 | Q72: GP595HE | R72: 21 | W72: sì | X72: scolastica lu-ve | Y72: 23.251566 | Z72: 2.58064 | AA72: =Y72*J72 -> 3813.2569 | AB72: da PDF (ordine posizionale)
A73: T.M. L.1 - Linee L1 e L2 LAVIS | B73: 200 | C73: L01111 | D73: 0.77708333 | E73: 0.78472222 | F73: LAVIS via Nazionale - PRESSANO Piazza | G73: /S colastica da Lunedì a Venerdì | H73: 3.76 | I73: 19 | J73: 164 | K73: =J73*H73 -> 616.64 | L73: 72 | N73: ELIMA SRL | O73: GL794HS | P73: 23 | Q73: GP595HE | R73: 21 | W73: sì | X73: scolastica lu-ve | Y73: 9.7032064 | Z73: 2.58064 | AA73: =Y73*J73 -> 1591.3258 | AB73: da PDF (ordine posizionale)
A74: T.M. L.1 - Linee L1 e L2 LAVIS | B74: 210 | C74: L01161 | D74: 0.78472222 | E74: 0.79027778 | F74: PRESSANO Piazza - LAVIS via Nazionale | G74: /S colastica da Lunedì a Venerdì | H74: 2.76 | I74: 19 | J74: 164 | K74: =J74*H74 -> 452.64 | L74: 73 | N74: ELIMA SRL | O74: GL794HS | P74: 23 | Q74: GP595HE | R74: 21 | W74: sì | X74: scolastica lu-ve | Y74: 7.1225664 | Z74: 2.58064 | AA74: =Y74*J74 -> 1168.1009 | AB74: da PDF (ordine posizionale)
A75: T.M. L.2 - Linee L2 e L3 e L4 LA | B75: 10 | C75: L02151 s6 | D75: 0.27708333 | E75: 0.28958333 | F75: SORNI - LAVIS via Nazionale | G75: VSIcSolastica da Lunedì a Venerdì | H75: 7.82 | I75: 19 | J75: 164 | K75: =J75*H75 -> 1282.48 | L75: 74 | N75: ELIMA SRL | O75: GL794HS | P75: 23 | Q75: GP595HE | R75: 21 | W75: sì | X75: scolastica lu-ve | Y75: 20.180605 | Z75: 2.58064 | AA75: =Y75*J75 -> 3309.6192 | AB75: da PDF (ordine posizionale)
A76: T.M. L.2 - Linee L2 e L3 e L4 LA | B76: 20 | C76: L04101 LV | D76: 0.30138889 | E76: 0.31041667 | F76: LAVIS via Nazionale - LAVIS via Nazionale | G76: VSIcSolastica da Lunedì a Venerdì | H76: 5.76 | I76: 19 | J76: 164 | K76: =J76*H76 -> 944.64 | L76: 75 | N76: ELIMA SRL | O76: GL794HS | P76: 23 | Q76: GP595HE | R76: 21 | W76: sì | X76: scolastica lu-ve | Y76: 14.864486 | Z76: 2.58064 | AA76: =Y76*J76 -> 2437.7758 | AB76: da PDF (ordine posizionale)
... A89: T.M. L.2 - Linee L2 e L3 e L4 LA | B89: 150 | C89: L03154 LV | D89: 0.76875 | E89: 0.77222222 | F89: LAVIS "Stazione FS" - LAVIS via Nazionale | G89: VSIcSolastica da Lunedì a Venerdì | H89: 2.22 | I89: 19 | J89: 164 | K89: =J89*H89 -> 364.08 | L89: 88 | N89: ELIMA SRL | O89: GL794HS | P89: 23 | Q89: GP595HE | R89: 21 | W89: sì | X89: scolastica lu-ve | Y89: 5.7290208 | Z89: 2.58064 | AA89: =Y89*J89 -> 939.55941 | AB89: da PDF (ordine posizionale)
A90: T.M. L.1 - Linea L1 LAVIS | B90: 10 | C90: L01151 s6 | D90: 0.27430556 | E90: 0.28958333 | F90: SORNI - LAVIS via Nazionale | G90: Scolastica solo il Sabato | H90: 9.76 | I90: 21 | J90: 34 | K90: =J90*H90 -> 331.84 | L90: 89 | N90: OSCAR VIAGGI DI FORMOLO OSCAR | O90: GX220WF | P90: 21 | Q90: GZ064ZJ | R90: 21 | S90: GX166WF | W90: sì | X90: scolastica sa | Y90: 25.187046 | Z90: 2.58064 | AA90: =Y90*J90 -> 856.35958 | AB90: da PDF (ordine posizionale)
A91: T.M. L.1 - Linea L1 LAVIS | B91: 20 | C91: L01102 | D91: 0.31805556 | E91: 0.33055556 | F91: LAVIS via Nazionale - SORNI | G91: Scolastica solo il Sabato | H91: 7.67 | I91: 19 | J91: 34 | K91: =J91*H91 -> 260.78 | L91: 90 | N91: ELIMA SRL | O91: GL794HS | P91: 23 | Q91: GP595HE | R91: 21 | W91: sì | X91: scolastica sa | Y91: 19.793509 | Z91: 2.58064 | AA91: =Y91*J91 -> 672.9793 | AB91: da PDF (ordine posizionale)
...

Sheet CEMBRA
A1: Servizio | B1: Linea | C1: n. corsa | D1: ora part. | E1: ora arr. | F1: percorso | G1: frequenza | H1: Km corsa/servizio | I1: Posti autobus | J1: nr. Gg | K1: Tot km | L1: n° riga | M1: Esito | N1: DITTA | O1: MEZZO TITOLARE | P1: posti mezzo titolare | Q1: MEZZO DI RISERVA 1 | R1: posti mezzo di riserva 1 | S1: MEZZO DI RISERVA 2 | T1: posti mezzo di riserva 2 | U1: MEZZO DI SUPPORTO | V1: posti mezzo di supporto | W1: conferma servizi ditta | X1: frequenza CTA | Y1: tariffa 2025/2026 | Z1: tariffa/km 2025/2026 | AA1: costo annuo | AB1: nota gg (set-mag)
A2: Servizi Comunità Valle di Cembra | B2: VALLE DI CEMBRA | C2: 107 | D2: 0.36458333 | E2: 0.41597222 | F2: Piscine-Sover-Valcava bivio-Gaggio/Gresta bivio- Scancio di Segonzano-Piazzo di Segonzano bivio- Sevignano-Lona-Sevignano-Piazzo di Segonzano bivio- Piazzo di Segonzano-Faver bivio-Fadana-Cembra- Lisignago RSA-Lisignago-Ceola-Verla-Mosana-Lavis | G2: feriale dal lunedì al venerdì | H2: 43.7 | I2: 19 | J2: 189 | K2: =J2*H2 -> 8259.3 | L2: 1 | N2: BAZZAVAN S.A.S. DI BAZZANELLA ANDREA | O2: GG058PN | P2: 24 | Q2: GC917HM | R2: 23 | W2: sì | X2: annuale feriale lu-ve | Y2: 97.68 | AA2: =Y2*J2 -> 18461.52 | AB2: da PDF
A3: Servizi Comunità Valle di Cembra | B3: VALLE DI CEMBRA | C3: 108 | D3: 0.41805556 | E3: 0.45277778 | F3: Lavis-Mosana-Verla-Ceola-Lisignago-Lisignago RSA- Cembra-Fadana-Faver bivio-Faver-Valda-Grumes- Grauno | G3: feriale dal lunedì al venerdì | H3: 30.2 | I3: 19 | J3: 189 | K3: =J3*H3 -> 5707.8 | L3: 2 | N3: BAZZAVAN S.A.S. DI BAZZANELLA ANDREA | O3: GG058PN | P3: 24 | Q3: GC917HM | R3: 23 | W3: sì | X3: annuale feriale lu-ve | Y3: 67.51 | AA3: =Y3*J3 -> 12759.39 | AB3: da PDF
A4: Servizi Comunità Valle di Cembra | B4: VALLE DI CEMBRA | C4: 109 | D4: 0.45277778 | E4: 0.4875 | F4: Grauno-Grumes-Valda-Faver-Faver bivio-Fadana- Cembra-Lisignago RSA-Lisignago-Ceola-Verla-Mosana- Lavis | G4: feriale dal lunedì al venerdì | H4: 29.7 | I4: 19 | J4: 189 | K4: =J4*H4 -> 5613.3 | L4: 3 | N4: BAZZAVAN S.A.S. DI BAZZANELLA ANDREA | O4: GG058PN | P4: 24 | Q4: GC917HM | R4: 23 | W4: sì | X4: annuale feriale lu-ve | Y4: 66.39 | AA4: =Y4*J4 -> 12547.71 | AB4: da PDF
A5: Servizi Comunità Valle di Cembra | B5: VALLE DI CEMBRA | C5: 106 | D5: 0.49861111 | E5: 0.52083333 | F5: Lisignago RSA-Cembra-Fadana-Faver bivio-Piazzo di Segonzano-Piazzo di Segonzano bivio-Sevignano-Lona- Lases-Albiano via roma -Albiano | G5: feriale dal lunedì al venerdì | H5: 18.15 | I5: 19 | J5: 189 | K5: =J5*H5 -> 3430.35 | L5: 4 | N5: BAZZAVAN S.A.S. DI BAZZANELLA ANDREA | O5: GG058PN | P5: 24 | Q5: GC917HM | R5: 23 | W5: sì | X5: annuale feriale lu-ve | Y5: 40.57 | AA5: =Y5*J5 -> 7667.73 | AB5: da PDF
A6: Servizi Comunità Valle di Cembra | B6: VALLE DI CEMBRA | C6: 107 | D6: 0.57291667 | E6: 0.62152778 | F6: Piscine-Sover-Valcava bivio-Gaggio/Gresta bivio- Scancio di Segonzano-Piazzo di Segonzano bivio- Sevignano-Lona-Lases-Albiano Via Roma-Albiano- Lases-Lona-Sevignano-Piazzo di Segonzano bivio- Piazzo di Segonzano-Faver bivio-Fadana-Cembra- Lisignago RSA | G6: feriale dal lunedì al venerdì | H6: 43.21 | I6: 19 | J6: 189 | K6: =J6*H6 -> 8166.69 | L6: 5 | N6: BAZZAVAN S.A.S. DI BAZZANELLA ANDREA | O6: GG058PN | P6: 24 | Q6: GC917HM | R6: 23 | W6: sì | X6: annuale feriale lu-ve | Y6: 96.59 | AA6: =Y6*J6 -> 18255.51 | AB6: da PDF
A7: Servizi Comunità Valle di Cembra | B7: VALLE DI CEMBRA | C7: 107 | D7: 0.62152778 | E7: 0.6375 | F7: Lisigignago RSA-Lisignago-Ceola-Verla-Mosana-Lavis | G7: estiva feriale dal lunedì al venerdì + invernale non scolastico dal lunedì al venerdì | H7: 12.9 | I7: 19 | J7: 25 | K7: =J7*H7 -> 322.5 | L7: 6 | N7: BAZZAVAN S.A.S. DI BAZZANELLA ANDREA | O7: GG058PN | P7: 24 | Q7: GC917HM | R7: 23 | W7: sì | X7: estiva feriale lu-ve + no scol lu-ve | Y7: 28.84 | AA7: =Y7*J7 -> 721 | AB7: da PDF
A8: Servizi Comunità Valle di Cembra | B8: VALLE DI CEMBRA | C8: 106 | D8: 0.62847222 | E8: 0.63680556 | F8: Cembra-Fadana-Faver bivio-Piazzo di Segonzano- Piazzo di Segonzano bivio-Segonzano | G8: scolastica dal lunedì al venerdì | H8: 8.5 | I8: 19 | J8: 164 | K8: =J8*H8 -> 1394 | L8: 7 | N8: BAZZAVAN S.A.S. DI BAZZANELLA ANDREA | O8: GG058PN | P8: 24 | Q8: GC917HM | R8: 23 | W8: sì | X8: scolastica lu-ve | Y8: 19 | AA8: =Y8*J8 -> 3116 | AB8: da PDF
A9: Servizi Comunità Valle di Cembra | B9: VALLE DI CEMBRA | C9: 108 | D9: 0.64305556 | E9: 0.67777778 | F9: Lavis-Mosana-Verla-Ceola-Lisignago-Lisignago RSA- Cembra-Fadana-Faver bivio-Faver-Valda-Grumes- Grauno | G9: estiva feriale dal lunedì al venerdì + invernale non scolastico dal lunedì al venerdì | H9: 30.2 | I9: 19 | J9: 25 | K9: =J9*H9 -> 755 | L9: 8 | N9: BAZZAVAN S.A.S. DI BAZZANELLA ANDREA | O9: GG058PN | P9: 24 | Q9: GC917HM | R9: 23 | W9: sì | X9: estiva feriale lu-ve + no scol lu-ve | Y9: 67.51 | AA9: =Y9*J9 -> 1687.75 | AB9: da PDF
A10: Servizi Comunità Valle di Cembra | B10: VALLE DI CEMBRA | C10: 109 | D10: 0.67847222 | E10: 0.71319444 | F10: Grauno-Grumes-Valda-Faver-Faver bivio-Fadana- Cembra-Lisignago RSA-Lisignago-Ceola-Verla-Mosana- Lavis | G10: estiva feriale dal lunedì al venerdì + invernale non scolastico dal lunedì al venerdì | H10: 29.7 | I10: 19 | J10: 25 | K10: =J10*H10 -> 742.5 | L10: 9 | N10: BAZZAVAN S.A.S. DI BAZZANELLA ANDREA | O10: GG058PN | P10: 24 | Q10: GC917HM | R10: 23 | W10: sì | X10: estiva feriale lu-ve + no scol lu-ve | Y10: 66.39 | AA10: =Y10*J10 -> 1659.75 | AB10: da PDF
A11: Servizi Comunità Valle di Cembra | B11: VALLE DI CEMBRA | C11: 106 | D11: 0.72777778 | E11: 0.75277778 | F11: Lisignago RSA-Cembra-Fadana-Faver bivio-Piazzo di Segonzano-Piazzo di Segonzano bivio-Segonzano- Sevignano-Lona-Lases-Albiano via Roma-Albiano | G11: feriale dal lunedì al venerdì | H11: 22.87 | I11: 19 | J11: 189 | K11: =J11*H11 -> 4322.43 | L11: 10 | N11: BAZZAVAN S.A.S. DI BAZZANELLA ANDREA | O11: GG058PN | P11: 24 | Q11: GC917HM | R11: 23 | W11: sì | X11: annuale feriale lu-ve | Y11: 51.12 | AA11: =Y11*J11 -> 9661.68 | AB11: da PDF
H12: TOTALE | K12: =SUM(K2:K11) -> 38713.87 | L12: sett-magg | AA12: =SUM(AA2:AA11) -> 86538.04 | AB12: sett-magg
K14: ='CEMBRA giu-ago'!K12 -> 16297.95 | L14: giu-ago | AA14: ='CEMBRA giu-ago'!AA12 -> 36431.6 | AB14: giu-ago
K16: =SUM(K12:K15) -> 55011.82 | AA16: =SUM(AA12:AA15) -> 122969.64
K18: 38713.87 | AA18: 86538.04
K20: 16297.95 | AA20: 36431.6
K22: 55011.82 | AA22: 122969.64
K24: =K18-K12 -> 0 | AA24: =AA18-AA12 -> 0
K25: =K14-K20 -> 0 | AA25: =AA14-AA20 -> 0
K26: =K16-K22 -> 0 | AA26: =AA16-AA22 -> 0

Sheet ALBIANO
A1: Servizio | B1: Linea | C1: n. corsa | D1: ora part. | E1: ora arr. | F1: percorso | G1: frequenza | H1: Km corsa/servizio | I1: Posti autobus | J1: nr. Gg | K1: Tot km | L1: n° riga | M1: Esito | N1: DITTA | O1: MEZZO TITOLARE | P1: posti mezzo titolare | Q1: MEZZO DI RISERVA 1 | R1: posti mezzo di riserva 1 | S1: MEZZO DI RISERVA 2 | T1: posti mezzo di riserva 2 | U1: MEZZO DI SUPPORTO | V1: posti mezzo di supporto | W1: conferma servizi ditta | X1: frequenza CTA | Y1: tariffa 2025/2026 | Z1: tariffa/km 2025/2026 | AA1: costo annuo | AB1: nota gg (set-mag)
A2: SERVIZIO ALBIANO LONA LASES | B2: LONA - ALBIANO - GAZZADINA | D2: 0.30208333 | E2: 0.31666667 | F2: Gazzadina-Gazzadina Via del Porfido 61-Albiano Via S. Antonio-Albiano P.zza Degasperi-Albiano Via Roma-Lases-Lona fermata bus-Lona Parcheggio | G2: feriale dal lunedì al venerdì | H2: 13 | I2: 19 | J2: 189 | K2: =J2*H2 -> 2457 | L2: 1 | N2: D'AMICO VIAGGI S.R.L. | O2: FT467CV | P2: 23 | Q2: FZ194KS (Fersina Tour) | R2: 24 | S2: GG115WS (Giulia sas) | T2: 21 | X2: annuale feriale lu-ve | Y2: 29.06 | AA2: =Y2*J2 -> 5492.34 | AB2: da PDF
A3: SERVIZIO ALBIANO LONA LASES | B3: LONA - ALBIANO - GAZZADINA | D3: 0.31736111 | E3: 0.33333333 | F3: Lona Parcheggio-Lona fermata Bus-Lases-Albiano Via Roma-Albiano Piazza Degasperi-Albiano (Via S. Antonio) - Gazzadina Via del Porfido 61 - Gazzadina | G3: feriale dal lunedì al venerdì | H3: 13 | I3: 19 | J3: 189 | K3: =J3*H3 -> 2457 | L3: 2 | N3: D'AMICO VIAGGI S.R.L. | O3: FT467CV | P3: 23 | Q3: FZ194KS (Fersina Tour) | R3: 24 | S3: GG115WS (Giulia sas) | T3: 22 | X3: annuale feriale lu-ve | Y3: 29.06 | AA3: =Y3*J3 -> 5492.34 | AB3: da PDF
A4: SERVIZIO ALBIANO LONA LASES | B4: LONA - ALBIANO - GAZZADINA | D4: 0.36458333 | E4: 0.37916667 | F4: Gazzadina-Gazzadina Via del Porfido 61-Albiano Via S. Antonio-Albiano P.zza Degasperi-Albiano Via Roma-Lases-Lona fermata bus-Lona Parcheggio | G4: feriale dal lunedì al venerdì | H4: 13 | I4: 19 | J4: 189 | K4: =J4*H4 -> 2457 | L4: 3 | N4: D'AMICO VIAGGI S.R.L. | O4: FT467CV | P4: 23 | Q4: FZ194KS (Fersina Tour) | R4: 24 | S4: GG115WS (Giulia sas) | T4: 23 | X4: annuale feriale lu-ve | Y4: 29.06 | AA4: =Y4*J4 -> 5492.34 | AB4: da PDF
A5: SERVIZIO ALBIANO LONA LASES | B5: LONA - ALBIANO - GAZZADINA | D5: 0.39097222 | E5: 0.40625 | F5: Lona Parcheggio-Lona fermata Bus-Lases-Albiano Via Roma-Albiano Piazza Degasperi-Albiano (Via S. Antonio) - Gazzadina Via del Porfido 61 - Gazzadina | G5: feriale dal lunedì al venerdì | H5: 13 | I5: 19 | J5: 189 | K5: =J5*H5 -> 2457 | L5: 4 | N5: D'AMICO VIAGGI S.R.L. | O5: FT467CV | P5: 23 | Q5: FZ194KS (Fersina Tour) | R5: 24 | S5: GG115WS (Giulia sas) | T5: 24 | X5: annuale feriale lu-ve | Y5: 29.06 | AA5: =Y5*J5 -> 5492.34 | AB5: da PDF
A6: SERVIZIO ALBIANO LONA LASES | B6: LONA - ALBIANO - GAZZADINA | D6: 0.5 | E6: 0.51458333 | F6: Gazzadina-Gazzadina Via del Porfido 61-Albiano Via S. Antonio-Albiano P.zza Degasperi-Albiano Via Roma-Lases-Lona fermata bus-Lona Parcheggio | G6: feriale dal lunedì al venerdì | H6: 13 | I6: 19 | J6: 189 | K6: =J6*H6 -> 2457 | L6: 5 | N6: D'AMICO VIAGGI S.R.L. | O6: FT467CV | P6: 23 | Q6: FZ194KS (Fersina Tour) | R6: 24 | S6: GG115WS (Giulia sas) | T6: 25 | X6: annuale feriale lu-ve | Y6: 29.06 | AA6: =Y6*J6 -> 5492.34 | AB6: da PDF
A7: SERVIZIO ALBIANO LONA LASES | B7: LONA - ALBIANO - GAZZADINA | D7: 0.52569444 | E7: 0.54166667 | F7: Lona Parcheggio-Lona fermata Bus-Lases-Albiano Via Roma-Albiano Piazza Degasperi-Albiano (Via S. Antonio) - Gazzadina Via del Porfido 61 - Gazzadina | G7: feriale dal lunedì al venerdì | H7: 13 | I7: 19 | J7: 189 | K7: =J7*H7 -> 2457 | L7: 6 | N7: D'AMICO VIAGGI S.R.L. | O7: FT467CV | P7: 23 | Q7: FZ194KS (Fersina Tour) | R7: 24 | S7: GG115WS (Giulia sas) | T7: 26 | X7: annuale feriale lu-ve | Y7: 29.06 | AA7: =Y7*J7 -> 5492.34 | AB7: da PDF
A8: SERVIZIO ALBIANO LONA LASES | B8: LONA - ALBIANO - GAZZADINA | D8: 0.58333333 | E8: 0.59375 | F8: Gazzadina-Gazzadina Via del Porfido 61-Albiano Via S. Antonio-Albiano P.zza Degasperi-Albiano Via Roma | G8: feriale dal lunedì al venerdì | H8: 9.6 | I8: 19 | J8: 189 | K8: =J8*H8 -> 1814.4 | L8: 7 | N8: D'AMICO VIAGGI S.R.L. | O8: FT467CV | P8: 23 | Q8: FZ194KS (Fersina Tour) | R8: 24 | S8: GG115WS (Giulia sas) | T8: 27 | X8: annuale feriale lu-ve | Y8: 21.46 | AA8: =Y8*J8 -> 4055.94 | AB8: da PDF
A9: SERVIZIO ALBIANO LONA LASES | B9: LONA - ALBIANO - GAZZADINA | D9: 0.61458333 | E9: 0.625 | F9: Albiano Via Roma-Albiano Piazza Degasperi-Albiano (Via S. Antonio) - Gazzadina Via del Porfido 61 - Gazzadina | G9: feriale dal lunedì al venerdì | H9: 9.6 | I9: 19 | J9: 189 | K9: =J9*H9 -> 1814.4 | L9: 8 | N9: D'AMICO VIAGGI S.R.L. | O9: FT467CV | P9: 23 | Q9: FZ194KS (Fersina Tour) | R9: 24 | S9: GG115WS (Giulia sas) | T9: 28 | X9: annuale feriale lu-ve | Y9: 21.46 | AA9: =Y9*J9 -> 4055.94 | AB9: da PDF
A10: SERVIZIO ALBIANO LONA LASES | B10: LONA - ALBIANO - GAZZADINA | D10: 0.66666667 | E10: 0.68055556 | F10: Gazzadina-Gazzadina Via del Porfido 61-Albiano Via S. Antonio-Albiano P.zza Degasperi-Albiano Via Roma-Lases-Lona fermata bus-Lona Parcheggio | G10: scolastica dal lunedì al giovedì | H10: 13 | I10: 19 | J10: 131 | K10: =J10*H10 -> 1703 | L10: 9 | N10: D'AMICO VIAGGI S.R.L. | O10: FT467CV | P10: 23 | Q10: FZ194KS (Fersina Tour) | R10: 24 | S10: GG115WS (Giulia sas) | T10: 29 | X10: scolastica lu, ma, me, gio | Y10: 29.06 | AA10: =Y10*J10 -> 3806.86 | AB10: da PDF
A11: SERVIZIO ALBIANO LONA LASES | B11: LONA - ALBIANO - GAZZADINA | D11: 0.66666667 | E11: 0.67708333 | F11: Gazzadina-Gazzadina Via del Porfido 61-Albiano Via S. Antonio-Albiano P.zza Degasperi-Albiano Via Roma | G11: feriale solo al venerdì | H11: 9.6 | I11: 19 | J11: 37 | K11: =J11*H11 -> 355.2 | L11: 10 | N11: D'AMICO VIAGGI S.R.L. | O11: FT467CV | P11: 23 | Q11: FZ194KS (Fersina Tour) | R11: 24 | S11: GG115WS (Giulia sas) | T11: 30 | X11: annuale feriale ve | Y11: 21.46 | AA11: =Y11*J11 -> 794.02 | AB11: da PDF
A12: SERVIZIO ALBIANO LONA LASES | B12: LONA - ALBIANO - GAZZADINA | D12: 0.66666667 | E12: 0.67708333 | F12: Gazzadina-Gazzadina Via del Porfido 61-Albiano Via S. Antonio-Albiano P.zza Degasperi-Albiano Via Roma | G12: estiva feriale dal lunedì al giovedì + invernale non scolastico dal lunedì al giovedì | H12: 9.6 | I12: 19 | J12: 21 | K12: =J12*H12 -> 201.6 | L12: 11 | N12: D'AMICO VIAGGI S.R.L. | O12: FT467CV | P12: 23 | Q12: FZ194KS (Fersina Tour) | R12: 24 | S12: GG115WS (Giulia sas) | T12: 31 | X12: estiva feriale lu, ma, me, gio + no scol lu, ma, me, gio | Y12: 21.46 | AA12: =Y12*J12 -> 450.66 | AB12: da PDF
A13: SERVIZIO ALBIANO LONA LASES | B13: LONA - ALBIANO - GAZZADINA | D13: 0.69861111 | E13: 0.70347222 | F13: Lona Parcheggio-Lona fermata Bus-Lases-Albiano Via Roma-Albiano Piazza Degasperi-Albiano (Via S. Antonio) - Gazzadina Via del Porfido 61 - Gazzadina | G13: scolastica dal lunedì al giovedì | H13: 13 | I13: 19 | J13: 131 | K13: =J13*H13 -> 1703 | L13: 12 | N13: D'AMICO VIAGGI S.R.L. | O13: FT467CV | P13: 23 | Q13: FZ194KS (Fersina Tour) | R13: 24 | S13: GG115WS (Giulia sas) | T13: 32 | X13: scolastica lu, ma, me, gio | Y13: 29.06 | AA13: =Y13*J13 -> 3806.86 | AB13: da PDF
... A29: SERVIZIO ALBIANO LONA LASES | B29: LONA - ALBIANO - GAZZADINA | D29: 0.79652778 | E29: 0.80208333 | F29: Lona Parcheggio-Lona fermata Bus-Lases-Albiano Via Roma-Albiano Piazza Degasperi- | G29: feriale solo al sabato | H29: 4.8 | I29: 19 | J29: 47 | K29: =J29*H29 -> 225.6 | L29: 28 | N29: D'AMICO VIAGGI S.R.L. | O29: FT467CV | P29: 23 | Q29: FZ194KS (Fersina Tour) | R29: 24 | S29: GG115WS (Giulia sas) | T29: 48 | X29: annuale feriale sa | Y29: 10.73 | AA29: =Y29*J29 -> 504.31 | AB29: da PDF
A30: SERVIZIO ALBIANO LONA LASES | B30: LONA - ALBIANO - GAZZADINA | F30: SERVIZIO A CHIAMATA PROLUNGAMENTO BARCO DI SOTTO TRATTA GAZZADINA - BARCO DI SOTTO - ALBIANO | G30: feriale dal lunedì al sabato | H30: 1 | I30: 19 | J30: 226 | K30: =J30*H30 -> 226 | L30: 29 | N30: D'AMICO VIAGGI S.R.L. | O30: FT467CV | P30: 23 | Q30: FZ194KS (Fersina Tour) | R30: 24 | S30: GG115WS (Giulia sas) | T30: 49 | X30: annuale feriale lu-sa | Y30: 2.24 | AA30: =Y30*J30 -> 506.24 | AB30: da PDF
A31: SERVIZIO ALBIANO LONA LASES | B31: LONA - ALBIANO - GAZZADINA | F31: SERVIZIO A CHIAMATA PROLUNGAMENTO PIAZZOLE | G31: feriale dal lunedì al sabato | H31: 1 | I31: 19 | J31: 226 | K31: =J31*H31 -> 226 | L31: 30 | N31: D'AMICO VIAGGI S.R.L. | O31: FT467CV | P31: 23 | Q31: FZ194KS (Fersina Tour) | R31: 24 | S31: GG115WS (Giulia sas) | T31: 50 | X31: annuale feriale lu-sa | Y31: 2.24 | AA31: =Y31*J31 -> 506.24 | AB31: da PDF
H32: TOTALE | K32: =SUM(K2:K31) -> 39611.6 | L32: sett-magg | AA32: =SUM(AA2:AA31) -> 88549.45 | AB32: sett-magg
K34: ='CEMBRA giu-ago'!K12 -> 16297.95 | L34: giu-ago | AA34: ='ALBIANO giu-ago'!AA32 -> 26948.81 | AB34: giu-ago
K36: =SUM(K32:K35) -> 55909.55 | AA36: =SUM(AA32:AA35) -> 115498.26
K38: 39611.6 | AA38: 88549.45
K40: 16297.95 | AA40: 26948.81
K42: 55909.55 | AA42: 115498.26
K44: =K38-K32 -> 0 | AA44: =AA38-AA32 -> 0
K45: =K34-K40 -> 0 | AA45: =AA34-AA40 -> 0
K46: =K36-K42 -> 0 | AA46: =AA36-AA42 -> 0

Sheet Targhe ditte
A1: nome ditta | B1: targa | C1: Posti carta di circolazione | D1: titolarità | E1: prima immatricolazione | F1: data revisione | G1: uso | H1: Verifica età mezzo (al 01/09/2026) | I1: Entro 8 anni al 01/09/2026 | J1: NOTE | K1: N° autorizzazione valida
A2: AUTOSERVIZI MATTUZZI CLAUDIO & C. S.N.C. | B2: FB808BJ | C2: 45 | D2: titolare | E2: 42354 | F2: 45650 | G2: SCUOLA/LINEA | H2: CONFORME (max 13 anni) | I2: NO | K2: 39/2025
A3: AUTOSERVIZI MATTUZZI CLAUDIO & C. S.N.C. | B3: FE584HG | C3: 56 | D3: riserva | E3: 42727 | F3: 46008 | G3: TURISMO/SCORTA LINEA | H3: CONFORME (max 13 anni) | I3: NO | K3: 43/2025
A4: AUTOSERVIZI MATTUZZI CLAUDIO & C. S.N.C. | B4: FL183NW | C4: 33 | D4: titolare | E4: 43045 | F4: 45602 | G4: LINEA | H4: CONFORME (max 13 anni) | I4: NO | K4: 40/2025
A5: AUTOSERVIZI MATTUZZI CLAUDIO & C. S.N.C. | B5: FZ760BE | C5: 54 | D5: riserva | E5: 43840 | F5: 45707 | G5: SCUOLA/SCORTA LINEA | H5: CONFORME (max 13 anni) | I5: SI | K5: 44/2025
A6: AUTOSERVIZI MATTUZZI CLAUDIO & C. S.N.C. | B6: GF141FZ | C6: 29 | D6: riserva | E6: 44418 | F6: 45868 | G6: TURISMO/SCORTA LINEA | H6: CONFORME (max 12 anni) | I6: SI | K6: 42/2025
A7: AUTOSERVIZI MATTUZZI CLAUDIO & C. S.N.C. | B7: GT606ZH | C7: 55 | D7: titolare | E7: 45505 | F7: 45896 | G7: SCUOLA/LINEA | H7: CONFORME (max 13 anni) | I7: SI | K7: 45/2025
A8: AUTOSERVIZI MATTUZZI CLAUDIO & C. S.N.C. | B8: GY436PZ | C8: 24 | D8: titolare | E8: 45855 | F8: 45855 | G8: SCUOLA/LINEA | H8: CONFORME (max 12 anni) | I8: SI | K8: 41/2025
A9: BAZZAVAN S.A.S. DI BAZZANELLA ANDREA | B9: GC917HM | C9: 23 | D9: riserva | E9: 44098 | F9: 45875 | G9: SCUOLA/SCORTA LINEA | H9: CONFORME (max 12 anni) | I9: SI | K9: 4235/P
